locust/test_results_20251007_125415/04_scenario3_aggressive_stats.csv
Type,Name,Request Count,Failure Count,Median Response Time,Average Response Time,Min Response Time,Max Response Time,Average Content Size,Requests/s,Failures/s,50%,66%,75%,80%,90%,95%,98%,99%,99.9%,99.99%,100%
POST,[S3] Aggressive Buy (AAPL),419,0,140.0,201.5685093078629,68.71350000074017,698.995400000058,62.0,1.401069394629477,0.0,140,200,260,320,410,460,570,680,700,700,700
POST,[S3] Aggressive Buy (GOOGL),426,0,43,79.86439577467416,24.547600000005332,637.4587999998766,63.0,1.4244762818905898,0.0,43,51,65,75,240,320,390,550,640,640,640
POST,[S3] Aggressive Buy (MSFT),466,0,40,68.05603240348049,21.720300001106807,637.1063000005961,62.0,1.558229923382664,0.0,40,48,55,63,110,290,360,410,640,640,640
POST,[S3] Aggressive Sell (AAPL),399,0,150.0,218.5551661654185,6.985199999689939,868.1679000001168,62.0,1.3341925738834397,0.0,150,240,320,350,420,540,630,740,870,870,870
POST,[S3] Aggressive Sell (GOOGL),405,0,46,88.13936246912851,21.38310000009369,756.2510000007023,63.0,1.3542556201072509,0.0,46,57,68,82,270,330,450,560,760,760,760
POST,[S3] Aggressive Sell (MSFT),421,0,43,84.11480736343722,23.694900000919006,652.3338999995758,62.0,1.4077570767040806,0.0,43,54,68,79,260,320,390,500,650,650,650
GET,[S3] Verify Trades,486,0,6300.0,6383.558999382688,2501.566900000398,10707.632800000283,10071533.711934157,1.625106744128701,0.0,6400,6700,6800,7000,7300,7700,8600,10000,11000,11000,11000
,Aggregated,3022,0,93,1128.6947418266122,6.985199999689939,10707.632800000283,1619762.887822634,10.105087614726203,0.0,93,170,320,400,6100,6700,7200,7600,10000,11000,11000
