locust/test_results_20251007_125415/05_scenario4_race_conditions_stats.csv
Type,Name,Request Count,Failure Count,Median Response Time,Average Response Time,Min Response Time,Max Response Time,Average Content Size,Requests/s,Failures/s,50%,66%,75%,80%,90%,95%,98%,99%,99.9%,99.99%,100%
POST,[S4] Rapid BUY (AAPL),1793,0,950.0,951.7764460122659,45.320299999730196,1333.682200000112,62.0,9.998239911095972,0.0,950,1000,1000,1100,1100,1200,1200,1300,1300,1300,1300
POST,[S4] Rapid BUY (GOOGL),1795,0,41,60.22925403900789,13.632199999847217,312.4518000004173,63.0,10.009392437488717,0.0,41,66,85,96,130,170,200,220,310,310,310
POST,[S4] Rapid BUY (MSFT),1840,0,39,57.98420152175269,12.376000000585918,314.2453000000387,62.0,10.260324281325483,0.0,39,63,82,94,130,160,200,220,290,310,310
POST,[S4] Rapid SELL (AAPL),1885,0,960.0,959.4373126259972,49.276400000962894,1370.6977999991068,62.0,10.511256125162246,0.0,960,1000,1100,1100,1100,1200,1300,1300,1300,1400,1400
POST,[S4] Rapid SELL (GOOGL),1751,0,41,61.38433620787698,13.189099998271558,330.83669999905396,63.0,9.764036856848325,0.0,41,66,84,97,140,170,210,230,330,330,330
POST,[S4] Rapid SELL (MSFT),1731,0,42,63.21631519353333,15.155999999478809,329.35940000061237,62.0,9.652511592920874,0.0,42,68,89,100,130,170,210,240,310,330,330
,Aggregated,10795,0,86,365.6126315979643,12.376000000585918,1370.6977999991068,62.328485409912,60.19576120484162,0.0,86,270,880,930,1000,1100,1200,1200,1300,1300,1400
